{
 "cells": [
  {
   "cell_type": "code",
   "execution_count": 1,
   "metadata": {},
   "outputs": [],
   "source": [
    "import pandas as pd\n",
    "from tqdm.auto import tqdm\n",
    "from nnsplit import NNSplit\n",
    "import numpy as np\n",
    "from threading import Thread\n",
    "import torch\n",
    "import pickle\n",
    "import h5py\n",
    "from io import BytesIO\n",
    "splitter = NNSplit.load(\"en\", use_cuda=True)"
   ]
  },
  {
   "cell_type": "code",
   "execution_count": 2,
   "metadata": {},
   "outputs": [],
   "source": [
    "import pymongo\n",
    "from pymongo import MongoClient\n",
    "client = MongoClient('mongodb+srv://cdminix:LTEG2pfoDiKfH29M@cluster0.pdjrf.mongodb.net/Reviews_Data?retryWrites=true&w=majority')"
   ]
  },
  {
   "cell_type": "code",
   "execution_count": 3,
   "metadata": {},
   "outputs": [],
   "source": [
    "db = client.Reviews_Data"
   ]
  },
  {
   "cell_type": "code",
   "execution_count": 4,
   "metadata": {},
   "outputs": [],
   "source": [
    "from bson.objectid import ObjectId\n",
    "import zlib"
   ]
  },
  {
   "cell_type": "code",
   "execution_count": 5,
   "metadata": {},
   "outputs": [],
   "source": [
    "from sentence_transformers import SentenceTransformer\n",
    "model = SentenceTransformer('paraphrase-distilroberta-base-v1')"
   ]
  },
  {
   "cell_type": "code",
   "execution_count": 6,
   "metadata": {},
   "outputs": [],
   "source": [
    "class LSH:\n",
    "    def __init__(self,\n",
    "                 hdf5_file=\"data.hdf5\",\n",
    "                 input_dim=768,\n",
    "                 hash_dim=6,\n",
    "                 seed=42,\n",
    "                 chunksize=1_000,\n",
    "                 dtype='int8',\n",
    "        ):\n",
    "        self.planes = []\n",
    "        self.input_dim = input_dim\n",
    "        np.random.seed(seed)\n",
    "        for i in range(hash_dim):\n",
    "            v = np.random.rand(input_dim)\n",
    "            v_hat = v / np.linalg.norm(v)\n",
    "            self.planes.append(v_hat)\n",
    "    \n",
    "        self.planes = np.matrix(self.planes)\n",
    "        self.data = h5py.File(hdf5_file, \"w\")\n",
    "        self.chunksize = chunksize\n",
    "        self.buckets = {}\n",
    "        self.id_buckets = {}\n",
    "        self.dtype = dtype\n",
    "    \n",
    "    # Returns LSH of a vector\n",
    "    def hash(self, vector):\n",
    "        hash_vector = np.where((self.planes @ vector) < 0, 1, 0)[0]\n",
    "        hash_string = \"\".join([str(num) for num in hash_vector])\n",
    "        return hash_string\n",
    "    \n",
    "    def quantize(self, vector_list):\n",
    "        vector_list = np.array(vector_list)\n",
    "        if self.dtype in ['float16', 'float32']:\n",
    "            return vector_list.astype(self.dtype)\n",
    "        if self.dtype == 'int8':\n",
    "            return np.asarray(vector_list * 128, dtype=np.int8)\n",
    "        raise ValueError(f'dtype needs to be float32, float16 or int8')\n",
    "    \n",
    "    # Add vector to bucket\n",
    "    def add(self, vector, i):\n",
    "        hashed = self.hash(vector)\n",
    "        \n",
    "        if hashed not in self.buckets:\n",
    "            self.buckets[hashed] = []\n",
    "            self.id_buckets[hashed] = []\n",
    "        \n",
    "        self.buckets[hashed].append(vector)\n",
    "        self.id_buckets[hashed].append(i)\n",
    "        \n",
    "        if len(self.buckets[hashed]) >= self.chunksize:\n",
    "            if hashed not in self.data:\n",
    "                self.data.create_dataset(hashed, (self.chunksize,self.input_dim), compression='gzip', dtype=self.dtype, chunks=True, maxshape=(None,self.input_dim))\n",
    "                self.data.create_dataset(hashed+'_id', (self.chunksize,), compression='gzip', dtype='int32', chunks=True, maxshape=(None,))\n",
    "            else:\n",
    "                hf = self.data[hashed]\n",
    "                hf_id = self.data[hashed+'_id']\n",
    "                hf.resize((hf.shape[0] + self.chunksize), axis=0)\n",
    "                hf_id.resize((hf_id.shape[0] + self.chunksize), axis=0)\n",
    "            self.data[hashed][-self.chunksize:] = self.quantize(self.buckets[hashed])\n",
    "            self.data[hashed+'_id'][-self.chunksize:] = self.id_buckets[hashed]\n",
    "            self.buckets[hashed] = []\n",
    "            self.id_buckets[hashed] = []\n",
    "            \n",
    "    def flush(self):\n",
    "        for hashed, vectors in self.buckets.items():\n",
    "            list_size = len(vectors)\n",
    "            if hashed not in self.data:\n",
    "                self.data.create_dataset(hashed, (list_size,self.input_dim), compression='gzip', dtype=self.dtype, chunks=True, maxshape=(None,self.input_dim))\n",
    "                self.data.create_dataset(hashed+'_id', (list_size,), compression='gzip', dtype='int32', chunks=True, maxshape=(None,))\n",
    "            else:\n",
    "                hf = self.data[hashed]\n",
    "                hf_id = self.data[hashed+'_id']\n",
    "                hf.resize((hf.shape[0] + list_size), axis=0)\n",
    "                hf_id.resize((hf_id.shape[0] + list_size), axis=0)\n",
    "            self.data[hashed][-list_size:] = self.quantize(self.buckets[hashed])\n",
    "            self.data[hashed+'_id'][-list_size:] = self.id_buckets[hashed]\n",
    "            self.buckets[hashed] = []\n",
    "            self.id_buckets[hashed] = []\n",
    "    \n",
    "    # Returns bucket vector is in\n",
    "    def get(self, vector):\n",
    "        hashed = self.hash(vector)\n",
    "        \n",
    "        if hashed in self.data:\n",
    "            return self.data[hashed]\n",
    "        \n",
    "        return []"
   ]
  },
  {
   "cell_type": "code",
   "execution_count": 7,
   "metadata": {},
   "outputs": [],
   "source": [
    "try:\n",
    "    db['sentence_data'].drop()\n",
    "    lsh_store.data.close()\n",
    "except:\n",
    "    pass"
   ]
  },
  {
   "cell_type": "code",
   "execution_count": null,
   "metadata": {},
   "outputs": [
    {
     "name": "stderr",
     "output_type": "stream",
     "text": [
      "/home/cdminix/anaconda3/envs/apaut/lib/python3.7/site-packages/ipykernel_launcher.py:10: DeprecationWarning: count is deprecated. Use estimated_document_count or count_documents instead. Please note that $where must be replaced by $expr, $near must be replaced by $geoWithin with $center, and $nearSphere must be replaced by $geoWithin with $centerSphere\n",
      "  # Remove the CWD from sys.path while we load stuff.\n"
     ]
    },
    {
     "data": {
      "application/vnd.jupyter.widget-view+json": {
       "model_id": "41a98b1005c24195ad40d60fc3f4a3a9",
       "version_major": 2,
       "version_minor": 0
      },
      "text/plain": [
       "HBox(children=(FloatProgress(value=0.0, max=11213281.0), HTML(value='')))"
      ]
     },
     "metadata": {},
     "output_type": "display_data"
    },
    {
     "name": "stderr",
     "output_type": "stream",
     "text": [
      "Traceback (most recent call last):\n",
      "  File \"/home/cdminix/anaconda3/envs/apaut/lib/python3.7/site-packages/pymongo/pool.py\", line 1180, in connect\n",
      "    sock = _configured_socket(self.address, self.opts)\n",
      "  File \"/home/cdminix/anaconda3/envs/apaut/lib/python3.7/site-packages/pymongo/pool.py\", line 988, in _configured_socket\n",
      "    sock = _create_connection(address, options)\n",
      "  File \"/home/cdminix/anaconda3/envs/apaut/lib/python3.7/site-packages/pymongo/pool.py\", line 944, in _create_connection\n",
      "    for res in socket.getaddrinfo(host, port, family, socket.SOCK_STREAM):\n",
      "  File \"/home/cdminix/anaconda3/envs/apaut/lib/python3.7/socket.py\", line 752, in getaddrinfo\n",
      "    for res in _socket.getaddrinfo(host, port, family, type, proto, flags):\n",
      "socket.gaierror: [Errno -3] Temporary failure in name resolution\n",
      "\n",
      "During handling of the above exception, another exception occurred:\n",
      "\n",
      "Traceback (most recent call last):\n",
      "  File \"/home/cdminix/anaconda3/envs/apaut/lib/python3.7/site-packages/pymongo/mongo_client.py\", line 1752, in _process_periodic_tasks\n",
      "    self._topology.update_pool(self.__all_credentials)\n",
      "  File \"/home/cdminix/anaconda3/envs/apaut/lib/python3.7/site-packages/pymongo/topology.py\", line 441, in update_pool\n",
      "    server._pool.remove_stale_sockets(generation, all_credentials)\n",
      "  File \"/home/cdminix/anaconda3/envs/apaut/lib/python3.7/site-packages/pymongo/pool.py\", line 1152, in remove_stale_sockets\n",
      "    sock_info = self.connect(all_credentials)\n",
      "  File \"/home/cdminix/anaconda3/envs/apaut/lib/python3.7/site-packages/pymongo/pool.py\", line 1187, in connect\n",
      "    _raise_connection_failure(self.address, error)\n",
      "  File \"/home/cdminix/anaconda3/envs/apaut/lib/python3.7/site-packages/pymongo/pool.py\", line 286, in _raise_connection_failure\n",
      "    raise AutoReconnect(msg)\n",
      "pymongo.errors.AutoReconnect: cluster0-shard-00-01.pdjrf.mongodb.net:27017: [Errno -3] Temporary failure in name resolution\n",
      "Exception in thread Thread-604:\n",
      "Traceback (most recent call last):\n",
      "  File \"/home/cdminix/anaconda3/envs/apaut/lib/python3.7/threading.py\", line 926, in _bootstrap_inner\n",
      "    self.run()\n",
      "  File \"/home/cdminix/anaconda3/envs/apaut/lib/python3.7/threading.py\", line 870, in run\n",
      "    self._target(*self._args, **self._kwargs)\n",
      "  File \"/home/cdminix/anaconda3/envs/apaut/lib/python3.7/site-packages/pymongo/collection.py\", line 761, in insert_many\n",
      "    blk.execute(write_concern, session=session)\n",
      "  File \"/home/cdminix/anaconda3/envs/apaut/lib/python3.7/site-packages/pymongo/bulk.py\", line 528, in execute\n",
      "    return self.execute_command(generator, write_concern, session)\n",
      "  File \"/home/cdminix/anaconda3/envs/apaut/lib/python3.7/site-packages/pymongo/bulk.py\", line 358, in execute_command\n",
      "    with client._tmp_session(session) as s:\n",
      "  File \"/home/cdminix/anaconda3/envs/apaut/lib/python3.7/contextlib.py\", line 112, in __enter__\n",
      "    return next(self.gen)\n",
      "  File \"/home/cdminix/anaconda3/envs/apaut/lib/python3.7/site-packages/pymongo/mongo_client.py\", line 1829, in _tmp_session\n",
      "    s = self._ensure_session(session)\n",
      "  File \"/home/cdminix/anaconda3/envs/apaut/lib/python3.7/site-packages/pymongo/mongo_client.py\", line 1816, in _ensure_session\n",
      "    return self.__start_session(True, causal_consistency=False)\n",
      "  File \"/home/cdminix/anaconda3/envs/apaut/lib/python3.7/site-packages/pymongo/mongo_client.py\", line 1766, in __start_session\n",
      "    server_session = self._get_server_session()\n",
      "  File \"/home/cdminix/anaconda3/envs/apaut/lib/python3.7/site-packages/pymongo/mongo_client.py\", line 1802, in _get_server_session\n",
      "    return self._topology.get_server_session()\n",
      "  File \"/home/cdminix/anaconda3/envs/apaut/lib/python3.7/site-packages/pymongo/topology.py\", line 493, in get_server_session\n",
      "    None)\n",
      "  File \"/home/cdminix/anaconda3/envs/apaut/lib/python3.7/site-packages/pymongo/topology.py\", line 217, in _select_servers_loop\n",
      "    (self._error_message(selector), timeout, self.description))\n",
      "pymongo.errors.ServerSelectionTimeoutError: cluster0-shard-00-01.pdjrf.mongodb.net:27017: [Errno -3] Temporary failure in name resolution,cluster0-shard-00-00.pdjrf.mongodb.net:27017: [Errno -3] Temporary failure in name resolution,cluster0-shard-00-02.pdjrf.mongodb.net:27017: [Errno -3] Temporary failure in name resolution, Timeout: 30s, Topology Description: <TopologyDescription id: 6019537e3d526681967b0979, topology_type: ReplicaSetNoPrimary, servers: [<ServerDescription ('cluster0-shard-00-00.pdjrf.mongodb.net', 27017) server_type: Unknown, rtt: None, error=AutoReconnect('cluster0-shard-00-00.pdjrf.mongodb.net:27017: [Errno -3] Temporary failure in name resolution')>, <ServerDescription ('cluster0-shard-00-01.pdjrf.mongodb.net', 27017) server_type: Unknown, rtt: None, error=AutoReconnect('cluster0-shard-00-01.pdjrf.mongodb.net:27017: [Errno -3] Temporary failure in name resolution')>, <ServerDescription ('cluster0-shard-00-02.pdjrf.mongodb.net', 27017) server_type: Unknown, rtt: None, error=AutoReconnect('cluster0-shard-00-02.pdjrf.mongodb.net:27017: [Errno -3] Temporary failure in name resolution')>]>\n",
      "\n",
      "Exception in thread Thread-605:\n",
      "Traceback (most recent call last):\n",
      "  File \"/home/cdminix/anaconda3/envs/apaut/lib/python3.7/threading.py\", line 926, in _bootstrap_inner\n",
      "    self.run()\n",
      "  File \"/home/cdminix/anaconda3/envs/apaut/lib/python3.7/threading.py\", line 870, in run\n",
      "    self._target(*self._args, **self._kwargs)\n",
      "  File \"/home/cdminix/anaconda3/envs/apaut/lib/python3.7/site-packages/pymongo/collection.py\", line 761, in insert_many\n",
      "    blk.execute(write_concern, session=session)\n",
      "  File \"/home/cdminix/anaconda3/envs/apaut/lib/python3.7/site-packages/pymongo/bulk.py\", line 528, in execute\n",
      "    return self.execute_command(generator, write_concern, session)\n",
      "  File \"/home/cdminix/anaconda3/envs/apaut/lib/python3.7/site-packages/pymongo/bulk.py\", line 358, in execute_command\n",
      "    with client._tmp_session(session) as s:\n",
      "  File \"/home/cdminix/anaconda3/envs/apaut/lib/python3.7/contextlib.py\", line 112, in __enter__\n",
      "    return next(self.gen)\n",
      "  File \"/home/cdminix/anaconda3/envs/apaut/lib/python3.7/site-packages/pymongo/mongo_client.py\", line 1829, in _tmp_session\n",
      "    s = self._ensure_session(session)\n",
      "  File \"/home/cdminix/anaconda3/envs/apaut/lib/python3.7/site-packages/pymongo/mongo_client.py\", line 1816, in _ensure_session\n",
      "    return self.__start_session(True, causal_consistency=False)\n",
      "  File \"/home/cdminix/anaconda3/envs/apaut/lib/python3.7/site-packages/pymongo/mongo_client.py\", line 1766, in __start_session\n",
      "    server_session = self._get_server_session()\n",
      "  File \"/home/cdminix/anaconda3/envs/apaut/lib/python3.7/site-packages/pymongo/mongo_client.py\", line 1802, in _get_server_session\n",
      "    return self._topology.get_server_session()\n",
      "  File \"/home/cdminix/anaconda3/envs/apaut/lib/python3.7/site-packages/pymongo/topology.py\", line 493, in get_server_session\n",
      "    None)\n",
      "  File \"/home/cdminix/anaconda3/envs/apaut/lib/python3.7/site-packages/pymongo/topology.py\", line 217, in _select_servers_loop\n",
      "    (self._error_message(selector), timeout, self.description))\n",
      "pymongo.errors.ServerSelectionTimeoutError: cluster0-shard-00-01.pdjrf.mongodb.net:27017: [Errno -3] Temporary failure in name resolution,cluster0-shard-00-00.pdjrf.mongodb.net:27017: [Errno -3] Temporary failure in name resolution,cluster0-shard-00-02.pdjrf.mongodb.net:27017: [Errno -3] Temporary failure in name resolution, Timeout: 30s, Topology Description: <TopologyDescription id: 6019537e3d526681967b0979, topology_type: ReplicaSetNoPrimary, servers: [<ServerDescription ('cluster0-shard-00-00.pdjrf.mongodb.net', 27017) server_type: Unknown, rtt: None, error=AutoReconnect('cluster0-shard-00-00.pdjrf.mongodb.net:27017: [Errno -3] Temporary failure in name resolution')>, <ServerDescription ('cluster0-shard-00-01.pdjrf.mongodb.net', 27017) server_type: Unknown, rtt: None, error=AutoReconnect('cluster0-shard-00-01.pdjrf.mongodb.net:27017: [Errno -3] Temporary failure in name resolution')>, <ServerDescription ('cluster0-shard-00-02.pdjrf.mongodb.net', 27017) server_type: Unknown, rtt: None, error=AutoReconnect('cluster0-shard-00-02.pdjrf.mongodb.net:27017: [Errno -3] Temporary failure in name resolution')>]>\n",
      "\n",
      "Exception in thread Thread-601:\n",
      "Traceback (most recent call last):\n",
      "  File \"/home/cdminix/anaconda3/envs/apaut/lib/python3.7/site-packages/pymongo/mongo_client.py\", line 1404, in _retry_internal\n",
      "    server = self._select_server(writable_server_selector, session)\n",
      "  File \"/home/cdminix/anaconda3/envs/apaut/lib/python3.7/site-packages/pymongo/mongo_client.py\", line 1278, in _select_server\n",
      "    server = topology.select_server(server_selector)\n",
      "  File \"/home/cdminix/anaconda3/envs/apaut/lib/python3.7/site-packages/pymongo/topology.py\", line 243, in select_server\n",
      "    address))\n",
      "  File \"/home/cdminix/anaconda3/envs/apaut/lib/python3.7/site-packages/pymongo/topology.py\", line 200, in select_servers\n",
      "    selector, server_timeout, address)\n",
      "  File \"/home/cdminix/anaconda3/envs/apaut/lib/python3.7/site-packages/pymongo/topology.py\", line 217, in _select_servers_loop\n",
      "    (self._error_message(selector), timeout, self.description))\n",
      "pymongo.errors.ServerSelectionTimeoutError: cluster0-shard-00-01.pdjrf.mongodb.net:27017: [Errno -3] Temporary failure in name resolution,cluster0-shard-00-00.pdjrf.mongodb.net:27017: [Errno -3] Temporary failure in name resolution,cluster0-shard-00-02.pdjrf.mongodb.net:27017: [Errno -3] Temporary failure in name resolution, Timeout: 30s, Topology Description: <TopologyDescription id: 6019537e3d526681967b0979, topology_type: ReplicaSetNoPrimary, servers: [<ServerDescription ('cluster0-shard-00-00.pdjrf.mongodb.net', 27017) server_type: Unknown, rtt: None, error=AutoReconnect('cluster0-shard-00-00.pdjrf.mongodb.net:27017: [Errno -3] Temporary failure in name resolution')>, <ServerDescription ('cluster0-shard-00-01.pdjrf.mongodb.net', 27017) server_type: Unknown, rtt: None, error=AutoReconnect('cluster0-shard-00-01.pdjrf.mongodb.net:27017: [Errno -3] Temporary failure in name resolution')>, <ServerDescription ('cluster0-shard-00-02.pdjrf.mongodb.net', 27017) server_type: Unknown, rtt: None, error=AutoReconnect('cluster0-shard-00-02.pdjrf.mongodb.net:27017: [Errno -3] Temporary failure in name resolution')>]>\n",
      "\n",
      "During handling of the above exception, another exception occurred:\n",
      "\n",
      "Traceback (most recent call last):\n",
      "  File \"/home/cdminix/anaconda3/envs/apaut/lib/python3.7/threading.py\", line 926, in _bootstrap_inner\n",
      "    self.run()\n",
      "  File \"/home/cdminix/anaconda3/envs/apaut/lib/python3.7/threading.py\", line 870, in run\n",
      "    self._target(*self._args, **self._kwargs)\n",
      "  File \"/home/cdminix/anaconda3/envs/apaut/lib/python3.7/site-packages/pymongo/collection.py\", line 761, in insert_many\n",
      "    blk.execute(write_concern, session=session)\n",
      "  File \"/home/cdminix/anaconda3/envs/apaut/lib/python3.7/site-packages/pymongo/bulk.py\", line 528, in execute\n",
      "    return self.execute_command(generator, write_concern, session)\n",
      "  File \"/home/cdminix/anaconda3/envs/apaut/lib/python3.7/site-packages/pymongo/bulk.py\", line 360, in execute_command\n",
      "    self.is_retryable, retryable_bulk, s, self)\n",
      "  File \"/home/cdminix/anaconda3/envs/apaut/lib/python3.7/site-packages/pymongo/mongo_client.py\", line 1384, in _retry_with_session\n",
      "    return self._retry_internal(retryable, func, session, bulk)\n",
      "  File \"/home/cdminix/anaconda3/envs/apaut/lib/python3.7/site-packages/pymongo/mongo_client.py\", line 1422, in _retry_internal\n",
      "    raise last_error\n",
      "  File \"/home/cdminix/anaconda3/envs/apaut/lib/python3.7/site-packages/pymongo/mongo_client.py\", line 1408, in _retry_internal\n",
      "    with self._get_socket(server, session) as sock_info:\n",
      "  File \"/home/cdminix/anaconda3/envs/apaut/lib/python3.7/contextlib.py\", line 112, in __enter__\n",
      "    return next(self.gen)\n",
      "  File \"/home/cdminix/anaconda3/envs/apaut/lib/python3.7/site-packages/pymongo/mongo_client.py\", line 1247, in _get_socket\n",
      "    self.__all_credentials, checkout=exhaust) as sock_info:\n",
      "  File \"/home/cdminix/anaconda3/envs/apaut/lib/python3.7/contextlib.py\", line 112, in __enter__\n",
      "    return next(self.gen)\n",
      "  File \"/home/cdminix/anaconda3/envs/apaut/lib/python3.7/site-packages/pymongo/pool.py\", line 1231, in get_socket\n",
      "    sock_info = self._get_socket(all_credentials)\n",
      "  File \"/home/cdminix/anaconda3/envs/apaut/lib/python3.7/site-packages/pymongo/pool.py\", line 1281, in _get_socket\n",
      "    sock_info = self.connect(all_credentials)\n",
      "  File \"/home/cdminix/anaconda3/envs/apaut/lib/python3.7/site-packages/pymongo/pool.py\", line 1187, in connect\n",
      "    _raise_connection_failure(self.address, error)\n",
      "  File \"/home/cdminix/anaconda3/envs/apaut/lib/python3.7/site-packages/pymongo/pool.py\", line 286, in _raise_connection_failure\n",
      "    raise AutoReconnect(msg)\n",
      "pymongo.errors.AutoReconnect: cluster0-shard-00-01.pdjrf.mongodb.net:27017: [Errno -3] Temporary failure in name resolution\n",
      "\n"
     ]
    },
    {
     "name": "stderr",
     "output_type": "stream",
     "text": [
      "Exception in thread Thread-602:\n",
      "Traceback (most recent call last):\n",
      "  File \"/home/cdminix/anaconda3/envs/apaut/lib/python3.7/site-packages/pymongo/mongo_client.py\", line 1404, in _retry_internal\n",
      "    server = self._select_server(writable_server_selector, session)\n",
      "  File \"/home/cdminix/anaconda3/envs/apaut/lib/python3.7/site-packages/pymongo/mongo_client.py\", line 1278, in _select_server\n",
      "    server = topology.select_server(server_selector)\n",
      "  File \"/home/cdminix/anaconda3/envs/apaut/lib/python3.7/site-packages/pymongo/topology.py\", line 243, in select_server\n",
      "    address))\n",
      "  File \"/home/cdminix/anaconda3/envs/apaut/lib/python3.7/site-packages/pymongo/topology.py\", line 200, in select_servers\n",
      "    selector, server_timeout, address)\n",
      "  File \"/home/cdminix/anaconda3/envs/apaut/lib/python3.7/site-packages/pymongo/topology.py\", line 217, in _select_servers_loop\n",
      "    (self._error_message(selector), timeout, self.description))\n",
      "pymongo.errors.ServerSelectionTimeoutError: cluster0-shard-00-01.pdjrf.mongodb.net:27017: [Errno -3] Temporary failure in name resolution,cluster0-shard-00-00.pdjrf.mongodb.net:27017: [Errno -3] Temporary failure in name resolution,cluster0-shard-00-02.pdjrf.mongodb.net:27017: [Errno -3] Temporary failure in name resolution, Timeout: 30s, Topology Description: <TopologyDescription id: 6019537e3d526681967b0979, topology_type: ReplicaSetNoPrimary, servers: [<ServerDescription ('cluster0-shard-00-00.pdjrf.mongodb.net', 27017) server_type: Unknown, rtt: None, error=AutoReconnect('cluster0-shard-00-00.pdjrf.mongodb.net:27017: [Errno -3] Temporary failure in name resolution')>, <ServerDescription ('cluster0-shard-00-01.pdjrf.mongodb.net', 27017) server_type: Unknown, rtt: None, error=AutoReconnect('cluster0-shard-00-01.pdjrf.mongodb.net:27017: [Errno -3] Temporary failure in name resolution')>, <ServerDescription ('cluster0-shard-00-02.pdjrf.mongodb.net', 27017) server_type: Unknown, rtt: None, error=AutoReconnect('cluster0-shard-00-02.pdjrf.mongodb.net:27017: [Errno -3] Temporary failure in name resolution')>]>\n",
      "\n",
      "During handling of the above exception, another exception occurred:\n",
      "\n",
      "Traceback (most recent call last):\n",
      "  File \"/home/cdminix/anaconda3/envs/apaut/lib/python3.7/threading.py\", line 926, in _bootstrap_inner\n",
      "    self.run()\n",
      "  File \"/home/cdminix/anaconda3/envs/apaut/lib/python3.7/threading.py\", line 870, in run\n",
      "    self._target(*self._args, **self._kwargs)\n",
      "  File \"/home/cdminix/anaconda3/envs/apaut/lib/python3.7/site-packages/pymongo/collection.py\", line 761, in insert_many\n",
      "    blk.execute(write_concern, session=session)\n",
      "  File \"/home/cdminix/anaconda3/envs/apaut/lib/python3.7/site-packages/pymongo/bulk.py\", line 528, in execute\n",
      "    return self.execute_command(generator, write_concern, session)\n",
      "  File \"/home/cdminix/anaconda3/envs/apaut/lib/python3.7/site-packages/pymongo/bulk.py\", line 360, in execute_command\n",
      "    self.is_retryable, retryable_bulk, s, self)\n",
      "  File \"/home/cdminix/anaconda3/envs/apaut/lib/python3.7/site-packages/pymongo/mongo_client.py\", line 1384, in _retry_with_session\n",
      "    return self._retry_internal(retryable, func, session, bulk)\n",
      "  File \"/home/cdminix/anaconda3/envs/apaut/lib/python3.7/site-packages/pymongo/mongo_client.py\", line 1422, in _retry_internal\n",
      "    raise last_error\n",
      "  File \"/home/cdminix/anaconda3/envs/apaut/lib/python3.7/site-packages/pymongo/mongo_client.py\", line 1408, in _retry_internal\n",
      "    with self._get_socket(server, session) as sock_info:\n",
      "  File \"/home/cdminix/anaconda3/envs/apaut/lib/python3.7/contextlib.py\", line 112, in __enter__\n",
      "    return next(self.gen)\n",
      "  File \"/home/cdminix/anaconda3/envs/apaut/lib/python3.7/site-packages/pymongo/mongo_client.py\", line 1247, in _get_socket\n",
      "    self.__all_credentials, checkout=exhaust) as sock_info:\n",
      "  File \"/home/cdminix/anaconda3/envs/apaut/lib/python3.7/contextlib.py\", line 112, in __enter__\n",
      "    return next(self.gen)\n",
      "  File \"/home/cdminix/anaconda3/envs/apaut/lib/python3.7/site-packages/pymongo/pool.py\", line 1231, in get_socket\n",
      "    sock_info = self._get_socket(all_credentials)\n",
      "  File \"/home/cdminix/anaconda3/envs/apaut/lib/python3.7/site-packages/pymongo/pool.py\", line 1281, in _get_socket\n",
      "    sock_info = self.connect(all_credentials)\n",
      "  File \"/home/cdminix/anaconda3/envs/apaut/lib/python3.7/site-packages/pymongo/pool.py\", line 1187, in connect\n",
      "    _raise_connection_failure(self.address, error)\n",
      "  File \"/home/cdminix/anaconda3/envs/apaut/lib/python3.7/site-packages/pymongo/pool.py\", line 286, in _raise_connection_failure\n",
      "    raise AutoReconnect(msg)\n",
      "pymongo.errors.AutoReconnect: cluster0-shard-00-01.pdjrf.mongodb.net:27017: [Errno -3] Temporary failure in name resolution\n",
      "\n",
      "Exception in thread Thread-603:\n",
      "Traceback (most recent call last):\n",
      "  File \"/home/cdminix/anaconda3/envs/apaut/lib/python3.7/site-packages/pymongo/mongo_client.py\", line 1404, in _retry_internal\n",
      "    server = self._select_server(writable_server_selector, session)\n",
      "  File \"/home/cdminix/anaconda3/envs/apaut/lib/python3.7/site-packages/pymongo/mongo_client.py\", line 1278, in _select_server\n",
      "    server = topology.select_server(server_selector)\n",
      "  File \"/home/cdminix/anaconda3/envs/apaut/lib/python3.7/site-packages/pymongo/topology.py\", line 243, in select_server\n",
      "    address))\n",
      "  File \"/home/cdminix/anaconda3/envs/apaut/lib/python3.7/site-packages/pymongo/topology.py\", line 200, in select_servers\n",
      "    selector, server_timeout, address)\n",
      "  File \"/home/cdminix/anaconda3/envs/apaut/lib/python3.7/site-packages/pymongo/topology.py\", line 217, in _select_servers_loop\n",
      "    (self._error_message(selector), timeout, self.description))\n",
      "pymongo.errors.ServerSelectionTimeoutError: cluster0-shard-00-01.pdjrf.mongodb.net:27017: [Errno -3] Temporary failure in name resolution,cluster0-shard-00-00.pdjrf.mongodb.net:27017: [Errno -3] Temporary failure in name resolution,cluster0-shard-00-02.pdjrf.mongodb.net:27017: [Errno -3] Temporary failure in name resolution, Timeout: 30s, Topology Description: <TopologyDescription id: 6019537e3d526681967b0979, topology_type: ReplicaSetNoPrimary, servers: [<ServerDescription ('cluster0-shard-00-00.pdjrf.mongodb.net', 27017) server_type: Unknown, rtt: None, error=AutoReconnect('cluster0-shard-00-00.pdjrf.mongodb.net:27017: [Errno -3] Temporary failure in name resolution')>, <ServerDescription ('cluster0-shard-00-01.pdjrf.mongodb.net', 27017) server_type: Unknown, rtt: None, error=AutoReconnect('cluster0-shard-00-01.pdjrf.mongodb.net:27017: [Errno -3] Temporary failure in name resolution')>, <ServerDescription ('cluster0-shard-00-02.pdjrf.mongodb.net', 27017) server_type: Unknown, rtt: None, error=AutoReconnect('cluster0-shard-00-02.pdjrf.mongodb.net:27017: [Errno -3] Temporary failure in name resolution')>]>\n",
      "\n",
      "During handling of the above exception, another exception occurred:\n",
      "\n",
      "Traceback (most recent call last):\n",
      "  File \"/home/cdminix/anaconda3/envs/apaut/lib/python3.7/threading.py\", line 926, in _bootstrap_inner\n",
      "    self.run()\n",
      "  File \"/home/cdminix/anaconda3/envs/apaut/lib/python3.7/threading.py\", line 870, in run\n",
      "    self._target(*self._args, **self._kwargs)\n",
      "  File \"/home/cdminix/anaconda3/envs/apaut/lib/python3.7/site-packages/pymongo/collection.py\", line 761, in insert_many\n",
      "    blk.execute(write_concern, session=session)\n",
      "  File \"/home/cdminix/anaconda3/envs/apaut/lib/python3.7/site-packages/pymongo/bulk.py\", line 528, in execute\n",
      "    return self.execute_command(generator, write_concern, session)\n",
      "  File \"/home/cdminix/anaconda3/envs/apaut/lib/python3.7/site-packages/pymongo/bulk.py\", line 360, in execute_command\n",
      "    self.is_retryable, retryable_bulk, s, self)\n",
      "  File \"/home/cdminix/anaconda3/envs/apaut/lib/python3.7/site-packages/pymongo/mongo_client.py\", line 1384, in _retry_with_session\n",
      "    return self._retry_internal(retryable, func, session, bulk)\n",
      "  File \"/home/cdminix/anaconda3/envs/apaut/lib/python3.7/site-packages/pymongo/mongo_client.py\", line 1422, in _retry_internal\n",
      "    raise last_error\n",
      "  File \"/home/cdminix/anaconda3/envs/apaut/lib/python3.7/site-packages/pymongo/mongo_client.py\", line 1408, in _retry_internal\n",
      "    with self._get_socket(server, session) as sock_info:\n",
      "  File \"/home/cdminix/anaconda3/envs/apaut/lib/python3.7/contextlib.py\", line 112, in __enter__\n",
      "    return next(self.gen)\n",
      "  File \"/home/cdminix/anaconda3/envs/apaut/lib/python3.7/site-packages/pymongo/mongo_client.py\", line 1247, in _get_socket\n",
      "    self.__all_credentials, checkout=exhaust) as sock_info:\n",
      "  File \"/home/cdminix/anaconda3/envs/apaut/lib/python3.7/contextlib.py\", line 112, in __enter__\n",
      "    return next(self.gen)\n",
      "  File \"/home/cdminix/anaconda3/envs/apaut/lib/python3.7/site-packages/pymongo/pool.py\", line 1231, in get_socket\n",
      "    sock_info = self._get_socket(all_credentials)\n",
      "  File \"/home/cdminix/anaconda3/envs/apaut/lib/python3.7/site-packages/pymongo/pool.py\", line 1281, in _get_socket\n",
      "    sock_info = self.connect(all_credentials)\n",
      "  File \"/home/cdminix/anaconda3/envs/apaut/lib/python3.7/site-packages/pymongo/pool.py\", line 1187, in connect\n",
      "    _raise_connection_failure(self.address, error)\n",
      "  File \"/home/cdminix/anaconda3/envs/apaut/lib/python3.7/site-packages/pymongo/pool.py\", line 286, in _raise_connection_failure\n",
      "    raise AutoReconnect(msg)\n",
      "pymongo.errors.AutoReconnect: cluster0-shard-00-01.pdjrf.mongodb.net:27017: [Errno -3] Temporary failure in name resolution\n",
      "\n"
     ]
    },
    {
     "name": "stderr",
     "output_type": "stream",
     "text": [
      "Exception in thread Thread-606:\n",
      "Traceback (most recent call last):\n",
      "  File \"/home/cdminix/anaconda3/envs/apaut/lib/python3.7/threading.py\", line 926, in _bootstrap_inner\n",
      "    self.run()\n",
      "  File \"/home/cdminix/anaconda3/envs/apaut/lib/python3.7/threading.py\", line 870, in run\n",
      "    self._target(*self._args, **self._kwargs)\n",
      "  File \"/home/cdminix/anaconda3/envs/apaut/lib/python3.7/site-packages/pymongo/collection.py\", line 761, in insert_many\n",
      "    blk.execute(write_concern, session=session)\n",
      "  File \"/home/cdminix/anaconda3/envs/apaut/lib/python3.7/site-packages/pymongo/bulk.py\", line 528, in execute\n",
      "    return self.execute_command(generator, write_concern, session)\n",
      "  File \"/home/cdminix/anaconda3/envs/apaut/lib/python3.7/site-packages/pymongo/bulk.py\", line 358, in execute_command\n",
      "    with client._tmp_session(session) as s:\n",
      "  File \"/home/cdminix/anaconda3/envs/apaut/lib/python3.7/contextlib.py\", line 112, in __enter__\n",
      "    return next(self.gen)\n",
      "  File \"/home/cdminix/anaconda3/envs/apaut/lib/python3.7/site-packages/pymongo/mongo_client.py\", line 1829, in _tmp_session\n",
      "    s = self._ensure_session(session)\n",
      "  File \"/home/cdminix/anaconda3/envs/apaut/lib/python3.7/site-packages/pymongo/mongo_client.py\", line 1816, in _ensure_session\n",
      "    return self.__start_session(True, causal_consistency=False)\n",
      "  File \"/home/cdminix/anaconda3/envs/apaut/lib/python3.7/site-packages/pymongo/mongo_client.py\", line 1766, in __start_session\n",
      "    server_session = self._get_server_session()\n",
      "  File \"/home/cdminix/anaconda3/envs/apaut/lib/python3.7/site-packages/pymongo/mongo_client.py\", line 1802, in _get_server_session\n",
      "    return self._topology.get_server_session()\n",
      "  File \"/home/cdminix/anaconda3/envs/apaut/lib/python3.7/site-packages/pymongo/topology.py\", line 493, in get_server_session\n",
      "    None)\n",
      "  File \"/home/cdminix/anaconda3/envs/apaut/lib/python3.7/site-packages/pymongo/topology.py\", line 217, in _select_servers_loop\n",
      "    (self._error_message(selector), timeout, self.description))\n",
      "pymongo.errors.ServerSelectionTimeoutError: cluster0-shard-00-01.pdjrf.mongodb.net:27017: [Errno -3] Temporary failure in name resolution,cluster0-shard-00-00.pdjrf.mongodb.net:27017: [Errno -3] Temporary failure in name resolution,cluster0-shard-00-02.pdjrf.mongodb.net:27017: [Errno -3] Temporary failure in name resolution, Timeout: 30s, Topology Description: <TopologyDescription id: 6019537e3d526681967b0979, topology_type: ReplicaSetNoPrimary, servers: [<ServerDescription ('cluster0-shard-00-00.pdjrf.mongodb.net', 27017) server_type: Unknown, rtt: None, error=AutoReconnect('cluster0-shard-00-00.pdjrf.mongodb.net:27017: [Errno -3] Temporary failure in name resolution')>, <ServerDescription ('cluster0-shard-00-01.pdjrf.mongodb.net', 27017) server_type: Unknown, rtt: None, error=AutoReconnect('cluster0-shard-00-01.pdjrf.mongodb.net:27017: [Errno -3] Temporary failure in name resolution')>, <ServerDescription ('cluster0-shard-00-02.pdjrf.mongodb.net', 27017) server_type: Unknown, rtt: None, error=AutoReconnect('cluster0-shard-00-02.pdjrf.mongodb.net:27017: [Errno -3] Temporary failure in name resolution')>]>\n",
      "\n",
      "Exception in thread Thread-607:\n",
      "Traceback (most recent call last):\n",
      "  File \"/home/cdminix/anaconda3/envs/apaut/lib/python3.7/threading.py\", line 926, in _bootstrap_inner\n",
      "    self.run()\n",
      "  File \"/home/cdminix/anaconda3/envs/apaut/lib/python3.7/threading.py\", line 870, in run\n",
      "    self._target(*self._args, **self._kwargs)\n",
      "  File \"/home/cdminix/anaconda3/envs/apaut/lib/python3.7/site-packages/pymongo/collection.py\", line 761, in insert_many\n",
      "    blk.execute(write_concern, session=session)\n",
      "  File \"/home/cdminix/anaconda3/envs/apaut/lib/python3.7/site-packages/pymongo/bulk.py\", line 528, in execute\n",
      "    return self.execute_command(generator, write_concern, session)\n",
      "  File \"/home/cdminix/anaconda3/envs/apaut/lib/python3.7/site-packages/pymongo/bulk.py\", line 358, in execute_command\n",
      "    with client._tmp_session(session) as s:\n",
      "  File \"/home/cdminix/anaconda3/envs/apaut/lib/python3.7/contextlib.py\", line 112, in __enter__\n",
      "    return next(self.gen)\n",
      "  File \"/home/cdminix/anaconda3/envs/apaut/lib/python3.7/site-packages/pymongo/mongo_client.py\", line 1829, in _tmp_session\n",
      "    s = self._ensure_session(session)\n",
      "  File \"/home/cdminix/anaconda3/envs/apaut/lib/python3.7/site-packages/pymongo/mongo_client.py\", line 1816, in _ensure_session\n",
      "    return self.__start_session(True, causal_consistency=False)\n",
      "  File \"/home/cdminix/anaconda3/envs/apaut/lib/python3.7/site-packages/pymongo/mongo_client.py\", line 1766, in __start_session\n",
      "    server_session = self._get_server_session()\n",
      "  File \"/home/cdminix/anaconda3/envs/apaut/lib/python3.7/site-packages/pymongo/mongo_client.py\", line 1802, in _get_server_session\n",
      "    return self._topology.get_server_session()\n",
      "  File \"/home/cdminix/anaconda3/envs/apaut/lib/python3.7/site-packages/pymongo/topology.py\", line 493, in get_server_session\n",
      "    None)\n",
      "  File \"/home/cdminix/anaconda3/envs/apaut/lib/python3.7/site-packages/pymongo/topology.py\", line 217, in _select_servers_loop\n",
      "    (self._error_message(selector), timeout, self.description))\n",
      "pymongo.errors.ServerSelectionTimeoutError: cluster0-shard-00-01.pdjrf.mongodb.net:27017: [Errno -3] Temporary failure in name resolution,cluster0-shard-00-00.pdjrf.mongodb.net:27017: [Errno -3] Temporary failure in name resolution,cluster0-shard-00-02.pdjrf.mongodb.net:27017: [Errno -3] Temporary failure in name resolution, Timeout: 30s, Topology Description: <TopologyDescription id: 6019537e3d526681967b0979, topology_type: ReplicaSetNoPrimary, servers: [<ServerDescription ('cluster0-shard-00-00.pdjrf.mongodb.net', 27017) server_type: Unknown, rtt: None, error=AutoReconnect('cluster0-shard-00-00.pdjrf.mongodb.net:27017: [Errno -3] Temporary failure in name resolution')>, <ServerDescription ('cluster0-shard-00-01.pdjrf.mongodb.net', 27017) server_type: Unknown, rtt: None, error=AutoReconnect('cluster0-shard-00-01.pdjrf.mongodb.net:27017: [Errno -3] Temporary failure in name resolution')>, <ServerDescription ('cluster0-shard-00-02.pdjrf.mongodb.net', 27017) server_type: Unknown, rtt: None, error=AutoReconnect('cluster0-shard-00-02.pdjrf.mongodb.net:27017: [Errno -3] Temporary failure in name resolution')>]>\n",
      "\n",
      "Exception in thread Thread-608:\n",
      "Traceback (most recent call last):\n",
      "  File \"/home/cdminix/anaconda3/envs/apaut/lib/python3.7/threading.py\", line 926, in _bootstrap_inner\n",
      "    self.run()\n",
      "  File \"/home/cdminix/anaconda3/envs/apaut/lib/python3.7/threading.py\", line 870, in run\n",
      "    self._target(*self._args, **self._kwargs)\n",
      "  File \"/home/cdminix/anaconda3/envs/apaut/lib/python3.7/site-packages/pymongo/collection.py\", line 761, in insert_many\n",
      "    blk.execute(write_concern, session=session)\n",
      "  File \"/home/cdminix/anaconda3/envs/apaut/lib/python3.7/site-packages/pymongo/bulk.py\", line 528, in execute\n",
      "    return self.execute_command(generator, write_concern, session)\n",
      "  File \"/home/cdminix/anaconda3/envs/apaut/lib/python3.7/site-packages/pymongo/bulk.py\", line 358, in execute_command\n",
      "    with client._tmp_session(session) as s:\n",
      "  File \"/home/cdminix/anaconda3/envs/apaut/lib/python3.7/contextlib.py\", line 112, in __enter__\n",
      "    return next(self.gen)\n",
      "  File \"/home/cdminix/anaconda3/envs/apaut/lib/python3.7/site-packages/pymongo/mongo_client.py\", line 1829, in _tmp_session\n",
      "    s = self._ensure_session(session)\n",
      "  File \"/home/cdminix/anaconda3/envs/apaut/lib/python3.7/site-packages/pymongo/mongo_client.py\", line 1816, in _ensure_session\n",
      "    return self.__start_session(True, causal_consistency=False)\n",
      "  File \"/home/cdminix/anaconda3/envs/apaut/lib/python3.7/site-packages/pymongo/mongo_client.py\", line 1766, in __start_session\n",
      "    server_session = self._get_server_session()\n",
      "  File \"/home/cdminix/anaconda3/envs/apaut/lib/python3.7/site-packages/pymongo/mongo_client.py\", line 1802, in _get_server_session\n",
      "    return self._topology.get_server_session()\n",
      "  File \"/home/cdminix/anaconda3/envs/apaut/lib/python3.7/site-packages/pymongo/topology.py\", line 493, in get_server_session\n",
      "    None)\n",
      "  File \"/home/cdminix/anaconda3/envs/apaut/lib/python3.7/site-packages/pymongo/topology.py\", line 217, in _select_servers_loop\n",
      "    (self._error_message(selector), timeout, self.description))\n",
      "pymongo.errors.ServerSelectionTimeoutError: cluster0-shard-00-01.pdjrf.mongodb.net:27017: [Errno -3] Temporary failure in name resolution,cluster0-shard-00-00.pdjrf.mongodb.net:27017: [Errno -3] Temporary failure in name resolution,cluster0-shard-00-02.pdjrf.mongodb.net:27017: [Errno -3] Temporary failure in name resolution, Timeout: 30s, Topology Description: <TopologyDescription id: 6019537e3d526681967b0979, topology_type: ReplicaSetNoPrimary, servers: [<ServerDescription ('cluster0-shard-00-00.pdjrf.mongodb.net', 27017) server_type: Unknown, rtt: None, error=AutoReconnect('cluster0-shard-00-00.pdjrf.mongodb.net:27017: [Errno -3] Temporary failure in name resolution')>, <ServerDescription ('cluster0-shard-00-01.pdjrf.mongodb.net', 27017) server_type: Unknown, rtt: None, error=AutoReconnect('cluster0-shard-00-01.pdjrf.mongodb.net:27017: [Errno -3] Temporary failure in name resolution')>, <ServerDescription ('cluster0-shard-00-02.pdjrf.mongodb.net', 27017) server_type: Unknown, rtt: None, error=AutoReconnect('cluster0-shard-00-02.pdjrf.mongodb.net:27017: [Errno -3] Temporary failure in name resolution')>]>\n",
      "\n"
     ]
    },
    {
     "name": "stderr",
     "output_type": "stream",
     "text": [
      "Exception in thread Thread-609:\n",
      "Traceback (most recent call last):\n",
      "  File \"/home/cdminix/anaconda3/envs/apaut/lib/python3.7/threading.py\", line 926, in _bootstrap_inner\n",
      "    self.run()\n",
      "  File \"/home/cdminix/anaconda3/envs/apaut/lib/python3.7/threading.py\", line 870, in run\n",
      "    self._target(*self._args, **self._kwargs)\n",
      "  File \"/home/cdminix/anaconda3/envs/apaut/lib/python3.7/site-packages/pymongo/collection.py\", line 761, in insert_many\n",
      "    blk.execute(write_concern, session=session)\n",
      "  File \"/home/cdminix/anaconda3/envs/apaut/lib/python3.7/site-packages/pymongo/bulk.py\", line 528, in execute\n",
      "    return self.execute_command(generator, write_concern, session)\n",
      "  File \"/home/cdminix/anaconda3/envs/apaut/lib/python3.7/site-packages/pymongo/bulk.py\", line 358, in execute_command\n",
      "    with client._tmp_session(session) as s:\n",
      "  File \"/home/cdminix/anaconda3/envs/apaut/lib/python3.7/contextlib.py\", line 112, in __enter__\n",
      "    return next(self.gen)\n",
      "  File \"/home/cdminix/anaconda3/envs/apaut/lib/python3.7/site-packages/pymongo/mongo_client.py\", line 1829, in _tmp_session\n",
      "    s = self._ensure_session(session)\n",
      "  File \"/home/cdminix/anaconda3/envs/apaut/lib/python3.7/site-packages/pymongo/mongo_client.py\", line 1816, in _ensure_session\n",
      "    return self.__start_session(True, causal_consistency=False)\n",
      "  File \"/home/cdminix/anaconda3/envs/apaut/lib/python3.7/site-packages/pymongo/mongo_client.py\", line 1766, in __start_session\n",
      "    server_session = self._get_server_session()\n",
      "  File \"/home/cdminix/anaconda3/envs/apaut/lib/python3.7/site-packages/pymongo/mongo_client.py\", line 1802, in _get_server_session\n",
      "    return self._topology.get_server_session()\n",
      "  File \"/home/cdminix/anaconda3/envs/apaut/lib/python3.7/site-packages/pymongo/topology.py\", line 493, in get_server_session\n",
      "    None)\n",
      "  File \"/home/cdminix/anaconda3/envs/apaut/lib/python3.7/site-packages/pymongo/topology.py\", line 217, in _select_servers_loop\n",
      "    (self._error_message(selector), timeout, self.description))\n",
      "pymongo.errors.ServerSelectionTimeoutError: cluster0-shard-00-01.pdjrf.mongodb.net:27017: [Errno -3] Temporary failure in name resolution,cluster0-shard-00-00.pdjrf.mongodb.net:27017: [Errno -3] Temporary failure in name resolution,cluster0-shard-00-02.pdjrf.mongodb.net:27017: [Errno -3] Temporary failure in name resolution, Timeout: 30s, Topology Description: <TopologyDescription id: 6019537e3d526681967b0979, topology_type: ReplicaSetNoPrimary, servers: [<ServerDescription ('cluster0-shard-00-00.pdjrf.mongodb.net', 27017) server_type: Unknown, rtt: None, error=AutoReconnect('cluster0-shard-00-00.pdjrf.mongodb.net:27017: [Errno -3] Temporary failure in name resolution')>, <ServerDescription ('cluster0-shard-00-01.pdjrf.mongodb.net', 27017) server_type: Unknown, rtt: None, error=AutoReconnect('cluster0-shard-00-01.pdjrf.mongodb.net:27017: [Errno -3] Temporary failure in name resolution')>, <ServerDescription ('cluster0-shard-00-02.pdjrf.mongodb.net', 27017) server_type: Unknown, rtt: None, error=AutoReconnect('cluster0-shard-00-02.pdjrf.mongodb.net:27017: [Errno -3] Temporary failure in name resolution')>]>\n",
      "\n",
      "Exception in thread Thread-610:\n",
      "Traceback (most recent call last):\n",
      "  File \"/home/cdminix/anaconda3/envs/apaut/lib/python3.7/threading.py\", line 926, in _bootstrap_inner\n",
      "    self.run()\n",
      "  File \"/home/cdminix/anaconda3/envs/apaut/lib/python3.7/threading.py\", line 870, in run\n",
      "    self._target(*self._args, **self._kwargs)\n",
      "  File \"/home/cdminix/anaconda3/envs/apaut/lib/python3.7/site-packages/pymongo/collection.py\", line 761, in insert_many\n",
      "    blk.execute(write_concern, session=session)\n",
      "  File \"/home/cdminix/anaconda3/envs/apaut/lib/python3.7/site-packages/pymongo/bulk.py\", line 528, in execute\n",
      "    return self.execute_command(generator, write_concern, session)\n",
      "  File \"/home/cdminix/anaconda3/envs/apaut/lib/python3.7/site-packages/pymongo/bulk.py\", line 358, in execute_command\n",
      "    with client._tmp_session(session) as s:\n",
      "  File \"/home/cdminix/anaconda3/envs/apaut/lib/python3.7/contextlib.py\", line 112, in __enter__\n",
      "    return next(self.gen)\n",
      "  File \"/home/cdminix/anaconda3/envs/apaut/lib/python3.7/site-packages/pymongo/mongo_client.py\", line 1829, in _tmp_session\n",
      "    s = self._ensure_session(session)\n",
      "  File \"/home/cdminix/anaconda3/envs/apaut/lib/python3.7/site-packages/pymongo/mongo_client.py\", line 1816, in _ensure_session\n",
      "    return self.__start_session(True, causal_consistency=False)\n",
      "  File \"/home/cdminix/anaconda3/envs/apaut/lib/python3.7/site-packages/pymongo/mongo_client.py\", line 1766, in __start_session\n",
      "    server_session = self._get_server_session()\n",
      "  File \"/home/cdminix/anaconda3/envs/apaut/lib/python3.7/site-packages/pymongo/mongo_client.py\", line 1802, in _get_server_session\n",
      "    return self._topology.get_server_session()\n",
      "  File \"/home/cdminix/anaconda3/envs/apaut/lib/python3.7/site-packages/pymongo/topology.py\", line 493, in get_server_session\n",
      "    None)\n",
      "  File \"/home/cdminix/anaconda3/envs/apaut/lib/python3.7/site-packages/pymongo/topology.py\", line 217, in _select_servers_loop\n",
      "    (self._error_message(selector), timeout, self.description))\n",
      "pymongo.errors.ServerSelectionTimeoutError: cluster0-shard-00-01.pdjrf.mongodb.net:27017: [Errno -3] Temporary failure in name resolution,cluster0-shard-00-00.pdjrf.mongodb.net:27017: [Errno -3] Temporary failure in name resolution,cluster0-shard-00-02.pdjrf.mongodb.net:27017: [Errno -3] Temporary failure in name resolution, Timeout: 30s, Topology Description: <TopologyDescription id: 6019537e3d526681967b0979, topology_type: ReplicaSetNoPrimary, servers: [<ServerDescription ('cluster0-shard-00-00.pdjrf.mongodb.net', 27017) server_type: Unknown, rtt: None, error=AutoReconnect('cluster0-shard-00-00.pdjrf.mongodb.net:27017: [Errno -3] Temporary failure in name resolution')>, <ServerDescription ('cluster0-shard-00-01.pdjrf.mongodb.net', 27017) server_type: Unknown, rtt: None, error=AutoReconnect('cluster0-shard-00-01.pdjrf.mongodb.net:27017: [Errno -3] Temporary failure in name resolution')>, <ServerDescription ('cluster0-shard-00-02.pdjrf.mongodb.net', 27017) server_type: Unknown, rtt: None, error=AutoReconnect('cluster0-shard-00-02.pdjrf.mongodb.net:27017: [Errno -3] Temporary failure in name resolution')>]>\n",
      "\n",
      "Exception in thread Thread-611:\n",
      "Traceback (most recent call last):\n",
      "  File \"/home/cdminix/anaconda3/envs/apaut/lib/python3.7/threading.py\", line 926, in _bootstrap_inner\n",
      "    self.run()\n",
      "  File \"/home/cdminix/anaconda3/envs/apaut/lib/python3.7/threading.py\", line 870, in run\n",
      "    self._target(*self._args, **self._kwargs)\n",
      "  File \"/home/cdminix/anaconda3/envs/apaut/lib/python3.7/site-packages/pymongo/collection.py\", line 761, in insert_many\n",
      "    blk.execute(write_concern, session=session)\n",
      "  File \"/home/cdminix/anaconda3/envs/apaut/lib/python3.7/site-packages/pymongo/bulk.py\", line 528, in execute\n",
      "    return self.execute_command(generator, write_concern, session)\n",
      "  File \"/home/cdminix/anaconda3/envs/apaut/lib/python3.7/site-packages/pymongo/bulk.py\", line 358, in execute_command\n",
      "    with client._tmp_session(session) as s:\n",
      "  File \"/home/cdminix/anaconda3/envs/apaut/lib/python3.7/contextlib.py\", line 112, in __enter__\n",
      "    return next(self.gen)\n",
      "  File \"/home/cdminix/anaconda3/envs/apaut/lib/python3.7/site-packages/pymongo/mongo_client.py\", line 1829, in _tmp_session\n",
      "    s = self._ensure_session(session)\n",
      "  File \"/home/cdminix/anaconda3/envs/apaut/lib/python3.7/site-packages/pymongo/mongo_client.py\", line 1816, in _ensure_session\n",
      "    return self.__start_session(True, causal_consistency=False)\n",
      "  File \"/home/cdminix/anaconda3/envs/apaut/lib/python3.7/site-packages/pymongo/mongo_client.py\", line 1766, in __start_session\n",
      "    server_session = self._get_server_session()\n",
      "  File \"/home/cdminix/anaconda3/envs/apaut/lib/python3.7/site-packages/pymongo/mongo_client.py\", line 1802, in _get_server_session\n",
      "    return self._topology.get_server_session()\n",
      "  File \"/home/cdminix/anaconda3/envs/apaut/lib/python3.7/site-packages/pymongo/topology.py\", line 493, in get_server_session\n",
      "    None)\n",
      "  File \"/home/cdminix/anaconda3/envs/apaut/lib/python3.7/site-packages/pymongo/topology.py\", line 217, in _select_servers_loop\n",
      "    (self._error_message(selector), timeout, self.description))\n",
      "pymongo.errors.ServerSelectionTimeoutError: cluster0-shard-00-01.pdjrf.mongodb.net:27017: [Errno -3] Temporary failure in name resolution,cluster0-shard-00-00.pdjrf.mongodb.net:27017: [Errno -3] Temporary failure in name resolution,cluster0-shard-00-02.pdjrf.mongodb.net:27017: [Errno -3] Temporary failure in name resolution, Timeout: 30s, Topology Description: <TopologyDescription id: 6019537e3d526681967b0979, topology_type: ReplicaSetNoPrimary, servers: [<ServerDescription ('cluster0-shard-00-00.pdjrf.mongodb.net', 27017) server_type: Unknown, rtt: None, error=AutoReconnect('cluster0-shard-00-00.pdjrf.mongodb.net:27017: [Errno -3] Temporary failure in name resolution')>, <ServerDescription ('cluster0-shard-00-01.pdjrf.mongodb.net', 27017) server_type: Unknown, rtt: None, error=AutoReconnect('cluster0-shard-00-01.pdjrf.mongodb.net:27017: [Errno -3] Temporary failure in name resolution')>, <ServerDescription ('cluster0-shard-00-02.pdjrf.mongodb.net', 27017) server_type: Unknown, rtt: None, error=AutoReconnect('cluster0-shard-00-02.pdjrf.mongodb.net:27017: [Errno -3] Temporary failure in name resolution')>]>\n",
      "\n"
     ]
    },
    {
     "name": "stderr",
     "output_type": "stream",
     "text": [
      "Exception in thread Thread-612:\n",
      "Traceback (most recent call last):\n",
      "  File \"/home/cdminix/anaconda3/envs/apaut/lib/python3.7/threading.py\", line 926, in _bootstrap_inner\n",
      "    self.run()\n",
      "  File \"/home/cdminix/anaconda3/envs/apaut/lib/python3.7/threading.py\", line 870, in run\n",
      "    self._target(*self._args, **self._kwargs)\n",
      "  File \"/home/cdminix/anaconda3/envs/apaut/lib/python3.7/site-packages/pymongo/collection.py\", line 761, in insert_many\n",
      "    blk.execute(write_concern, session=session)\n",
      "  File \"/home/cdminix/anaconda3/envs/apaut/lib/python3.7/site-packages/pymongo/bulk.py\", line 528, in execute\n",
      "    return self.execute_command(generator, write_concern, session)\n",
      "  File \"/home/cdminix/anaconda3/envs/apaut/lib/python3.7/site-packages/pymongo/bulk.py\", line 358, in execute_command\n",
      "    with client._tmp_session(session) as s:\n",
      "  File \"/home/cdminix/anaconda3/envs/apaut/lib/python3.7/contextlib.py\", line 112, in __enter__\n",
      "    return next(self.gen)\n",
      "  File \"/home/cdminix/anaconda3/envs/apaut/lib/python3.7/site-packages/pymongo/mongo_client.py\", line 1829, in _tmp_session\n",
      "    s = self._ensure_session(session)\n",
      "  File \"/home/cdminix/anaconda3/envs/apaut/lib/python3.7/site-packages/pymongo/mongo_client.py\", line 1816, in _ensure_session\n",
      "    return self.__start_session(True, causal_consistency=False)\n",
      "  File \"/home/cdminix/anaconda3/envs/apaut/lib/python3.7/site-packages/pymongo/mongo_client.py\", line 1766, in __start_session\n",
      "    server_session = self._get_server_session()\n",
      "  File \"/home/cdminix/anaconda3/envs/apaut/lib/python3.7/site-packages/pymongo/mongo_client.py\", line 1802, in _get_server_session\n",
      "    return self._topology.get_server_session()\n",
      "  File \"/home/cdminix/anaconda3/envs/apaut/lib/python3.7/site-packages/pymongo/topology.py\", line 493, in get_server_session\n",
      "    None)\n",
      "  File \"/home/cdminix/anaconda3/envs/apaut/lib/python3.7/site-packages/pymongo/topology.py\", line 217, in _select_servers_loop\n",
      "    (self._error_message(selector), timeout, self.description))\n",
      "pymongo.errors.ServerSelectionTimeoutError: cluster0-shard-00-01.pdjrf.mongodb.net:27017: [Errno -3] Temporary failure in name resolution,cluster0-shard-00-00.pdjrf.mongodb.net:27017: [Errno -3] Temporary failure in name resolution,cluster0-shard-00-02.pdjrf.mongodb.net:27017: [Errno -3] Temporary failure in name resolution, Timeout: 30s, Topology Description: <TopologyDescription id: 6019537e3d526681967b0979, topology_type: ReplicaSetNoPrimary, servers: [<ServerDescription ('cluster0-shard-00-00.pdjrf.mongodb.net', 27017) server_type: Unknown, rtt: None, error=AutoReconnect('cluster0-shard-00-00.pdjrf.mongodb.net:27017: [Errno -3] Temporary failure in name resolution')>, <ServerDescription ('cluster0-shard-00-01.pdjrf.mongodb.net', 27017) server_type: Unknown, rtt: None, error=AutoReconnect('cluster0-shard-00-01.pdjrf.mongodb.net:27017: [Errno -3] Temporary failure in name resolution')>, <ServerDescription ('cluster0-shard-00-02.pdjrf.mongodb.net', 27017) server_type: Unknown, rtt: None, error=AutoReconnect('cluster0-shard-00-02.pdjrf.mongodb.net:27017: [Errno -3] Temporary failure in name resolution')>]>\n",
      "\n",
      "Exception in thread Thread-613:\n",
      "Traceback (most recent call last):\n",
      "  File \"/home/cdminix/anaconda3/envs/apaut/lib/python3.7/threading.py\", line 926, in _bootstrap_inner\n",
      "    self.run()\n",
      "  File \"/home/cdminix/anaconda3/envs/apaut/lib/python3.7/threading.py\", line 870, in run\n",
      "    self._target(*self._args, **self._kwargs)\n",
      "  File \"/home/cdminix/anaconda3/envs/apaut/lib/python3.7/site-packages/pymongo/collection.py\", line 761, in insert_many\n",
      "    blk.execute(write_concern, session=session)\n",
      "  File \"/home/cdminix/anaconda3/envs/apaut/lib/python3.7/site-packages/pymongo/bulk.py\", line 528, in execute\n",
      "    return self.execute_command(generator, write_concern, session)\n",
      "  File \"/home/cdminix/anaconda3/envs/apaut/lib/python3.7/site-packages/pymongo/bulk.py\", line 358, in execute_command\n",
      "    with client._tmp_session(session) as s:\n",
      "  File \"/home/cdminix/anaconda3/envs/apaut/lib/python3.7/contextlib.py\", line 112, in __enter__\n",
      "    return next(self.gen)\n",
      "  File \"/home/cdminix/anaconda3/envs/apaut/lib/python3.7/site-packages/pymongo/mongo_client.py\", line 1829, in _tmp_session\n",
      "    s = self._ensure_session(session)\n",
      "  File \"/home/cdminix/anaconda3/envs/apaut/lib/python3.7/site-packages/pymongo/mongo_client.py\", line 1816, in _ensure_session\n",
      "    return self.__start_session(True, causal_consistency=False)\n",
      "  File \"/home/cdminix/anaconda3/envs/apaut/lib/python3.7/site-packages/pymongo/mongo_client.py\", line 1766, in __start_session\n",
      "    server_session = self._get_server_session()\n",
      "  File \"/home/cdminix/anaconda3/envs/apaut/lib/python3.7/site-packages/pymongo/mongo_client.py\", line 1802, in _get_server_session\n",
      "    return self._topology.get_server_session()\n",
      "  File \"/home/cdminix/anaconda3/envs/apaut/lib/python3.7/site-packages/pymongo/topology.py\", line 493, in get_server_session\n",
      "    None)\n",
      "  File \"/home/cdminix/anaconda3/envs/apaut/lib/python3.7/site-packages/pymongo/topology.py\", line 217, in _select_servers_loop\n",
      "    (self._error_message(selector), timeout, self.description))\n",
      "pymongo.errors.ServerSelectionTimeoutError: cluster0-shard-00-01.pdjrf.mongodb.net:27017: [Errno -3] Temporary failure in name resolution,cluster0-shard-00-00.pdjrf.mongodb.net:27017: [Errno -3] Temporary failure in name resolution,cluster0-shard-00-02.pdjrf.mongodb.net:27017: [Errno -3] Temporary failure in name resolution, Timeout: 30s, Topology Description: <TopologyDescription id: 6019537e3d526681967b0979, topology_type: ReplicaSetNoPrimary, servers: [<ServerDescription ('cluster0-shard-00-00.pdjrf.mongodb.net', 27017) server_type: Unknown, rtt: None, error=AutoReconnect('cluster0-shard-00-00.pdjrf.mongodb.net:27017: [Errno -3] Temporary failure in name resolution')>, <ServerDescription ('cluster0-shard-00-01.pdjrf.mongodb.net', 27017) server_type: Unknown, rtt: None, error=AutoReconnect('cluster0-shard-00-01.pdjrf.mongodb.net:27017: [Errno -3] Temporary failure in name resolution')>, <ServerDescription ('cluster0-shard-00-02.pdjrf.mongodb.net', 27017) server_type: Unknown, rtt: None, error=AutoReconnect('cluster0-shard-00-02.pdjrf.mongodb.net:27017: [Errno -3] Temporary failure in name resolution')>]>\n",
      "\n",
      "Exception in thread Thread-614:\n",
      "Traceback (most recent call last):\n",
      "  File \"/home/cdminix/anaconda3/envs/apaut/lib/python3.7/threading.py\", line 926, in _bootstrap_inner\n",
      "    self.run()\n",
      "  File \"/home/cdminix/anaconda3/envs/apaut/lib/python3.7/threading.py\", line 870, in run\n",
      "    self._target(*self._args, **self._kwargs)\n",
      "  File \"/home/cdminix/anaconda3/envs/apaut/lib/python3.7/site-packages/pymongo/collection.py\", line 761, in insert_many\n",
      "    blk.execute(write_concern, session=session)\n",
      "  File \"/home/cdminix/anaconda3/envs/apaut/lib/python3.7/site-packages/pymongo/bulk.py\", line 528, in execute\n",
      "    return self.execute_command(generator, write_concern, session)\n",
      "  File \"/home/cdminix/anaconda3/envs/apaut/lib/python3.7/site-packages/pymongo/bulk.py\", line 358, in execute_command\n",
      "    with client._tmp_session(session) as s:\n",
      "  File \"/home/cdminix/anaconda3/envs/apaut/lib/python3.7/contextlib.py\", line 112, in __enter__\n",
      "    return next(self.gen)\n",
      "  File \"/home/cdminix/anaconda3/envs/apaut/lib/python3.7/site-packages/pymongo/mongo_client.py\", line 1829, in _tmp_session\n",
      "    s = self._ensure_session(session)\n",
      "  File \"/home/cdminix/anaconda3/envs/apaut/lib/python3.7/site-packages/pymongo/mongo_client.py\", line 1816, in _ensure_session\n",
      "    return self.__start_session(True, causal_consistency=False)\n",
      "  File \"/home/cdminix/anaconda3/envs/apaut/lib/python3.7/site-packages/pymongo/mongo_client.py\", line 1766, in __start_session\n",
      "    server_session = self._get_server_session()\n",
      "  File \"/home/cdminix/anaconda3/envs/apaut/lib/python3.7/site-packages/pymongo/mongo_client.py\", line 1802, in _get_server_session\n",
      "    return self._topology.get_server_session()\n",
      "  File \"/home/cdminix/anaconda3/envs/apaut/lib/python3.7/site-packages/pymongo/topology.py\", line 493, in get_server_session\n",
      "    None)\n",
      "  File \"/home/cdminix/anaconda3/envs/apaut/lib/python3.7/site-packages/pymongo/topology.py\", line 217, in _select_servers_loop\n",
      "    (self._error_message(selector), timeout, self.description))\n",
      "pymongo.errors.ServerSelectionTimeoutError: cluster0-shard-00-01.pdjrf.mongodb.net:27017: [Errno -3] Temporary failure in name resolution,cluster0-shard-00-00.pdjrf.mongodb.net:27017: [Errno -3] Temporary failure in name resolution,cluster0-shard-00-02.pdjrf.mongodb.net:27017: [Errno -3] Temporary failure in name resolution, Timeout: 30s, Topology Description: <TopologyDescription id: 6019537e3d526681967b0979, topology_type: ReplicaSetNoPrimary, servers: [<ServerDescription ('cluster0-shard-00-00.pdjrf.mongodb.net', 27017) server_type: Unknown, rtt: None, error=AutoReconnect('cluster0-shard-00-00.pdjrf.mongodb.net:27017: [Errno -3] Temporary failure in name resolution')>, <ServerDescription ('cluster0-shard-00-01.pdjrf.mongodb.net', 27017) server_type: Unknown, rtt: None, error=AutoReconnect('cluster0-shard-00-01.pdjrf.mongodb.net:27017: [Errno -3] Temporary failure in name resolution')>, <ServerDescription ('cluster0-shard-00-02.pdjrf.mongodb.net', 27017) server_type: Unknown, rtt: None, error=AutoReconnect('cluster0-shard-00-02.pdjrf.mongodb.net:27017: [Errno -3] Temporary failure in name resolution')>]>\n",
      "\n"
     ]
    },
    {
     "name": "stderr",
     "output_type": "stream",
     "text": [
      "Exception in thread Thread-615:\n",
      "Traceback (most recent call last):\n",
      "  File \"/home/cdminix/anaconda3/envs/apaut/lib/python3.7/threading.py\", line 926, in _bootstrap_inner\n",
      "    self.run()\n",
      "  File \"/home/cdminix/anaconda3/envs/apaut/lib/python3.7/threading.py\", line 870, in run\n",
      "    self._target(*self._args, **self._kwargs)\n",
      "  File \"/home/cdminix/anaconda3/envs/apaut/lib/python3.7/site-packages/pymongo/collection.py\", line 761, in insert_many\n",
      "    blk.execute(write_concern, session=session)\n",
      "  File \"/home/cdminix/anaconda3/envs/apaut/lib/python3.7/site-packages/pymongo/bulk.py\", line 528, in execute\n",
      "    return self.execute_command(generator, write_concern, session)\n",
      "  File \"/home/cdminix/anaconda3/envs/apaut/lib/python3.7/site-packages/pymongo/bulk.py\", line 358, in execute_command\n",
      "    with client._tmp_session(session) as s:\n",
      "  File \"/home/cdminix/anaconda3/envs/apaut/lib/python3.7/contextlib.py\", line 112, in __enter__\n",
      "    return next(self.gen)\n",
      "  File \"/home/cdminix/anaconda3/envs/apaut/lib/python3.7/site-packages/pymongo/mongo_client.py\", line 1829, in _tmp_session\n",
      "    s = self._ensure_session(session)\n",
      "  File \"/home/cdminix/anaconda3/envs/apaut/lib/python3.7/site-packages/pymongo/mongo_client.py\", line 1816, in _ensure_session\n",
      "    return self.__start_session(True, causal_consistency=False)\n",
      "  File \"/home/cdminix/anaconda3/envs/apaut/lib/python3.7/site-packages/pymongo/mongo_client.py\", line 1766, in __start_session\n",
      "    server_session = self._get_server_session()\n",
      "  File \"/home/cdminix/anaconda3/envs/apaut/lib/python3.7/site-packages/pymongo/mongo_client.py\", line 1802, in _get_server_session\n",
      "    return self._topology.get_server_session()\n",
      "  File \"/home/cdminix/anaconda3/envs/apaut/lib/python3.7/site-packages/pymongo/topology.py\", line 493, in get_server_session\n",
      "    None)\n",
      "  File \"/home/cdminix/anaconda3/envs/apaut/lib/python3.7/site-packages/pymongo/topology.py\", line 217, in _select_servers_loop\n",
      "    (self._error_message(selector), timeout, self.description))\n",
      "pymongo.errors.ServerSelectionTimeoutError: cluster0-shard-00-01.pdjrf.mongodb.net:27017: [Errno -3] Temporary failure in name resolution,cluster0-shard-00-00.pdjrf.mongodb.net:27017: [Errno -3] Temporary failure in name resolution,cluster0-shard-00-02.pdjrf.mongodb.net:27017: [Errno -3] Temporary failure in name resolution, Timeout: 30s, Topology Description: <TopologyDescription id: 6019537e3d526681967b0979, topology_type: ReplicaSetNoPrimary, servers: [<ServerDescription ('cluster0-shard-00-00.pdjrf.mongodb.net', 27017) server_type: Unknown, rtt: None, error=AutoReconnect('cluster0-shard-00-00.pdjrf.mongodb.net:27017: [Errno -3] Temporary failure in name resolution')>, <ServerDescription ('cluster0-shard-00-01.pdjrf.mongodb.net', 27017) server_type: Unknown, rtt: None, error=AutoReconnect('cluster0-shard-00-01.pdjrf.mongodb.net:27017: [Errno -3] Temporary failure in name resolution')>, <ServerDescription ('cluster0-shard-00-02.pdjrf.mongodb.net', 27017) server_type: Unknown, rtt: None, error=AutoReconnect('cluster0-shard-00-02.pdjrf.mongodb.net:27017: [Errno -3] Temporary failure in name resolution')>]>\n",
      "\n",
      "Exception in thread Thread-616:\n",
      "Traceback (most recent call last):\n",
      "  File \"/home/cdminix/anaconda3/envs/apaut/lib/python3.7/threading.py\", line 926, in _bootstrap_inner\n",
      "    self.run()\n",
      "  File \"/home/cdminix/anaconda3/envs/apaut/lib/python3.7/threading.py\", line 870, in run\n",
      "    self._target(*self._args, **self._kwargs)\n",
      "  File \"/home/cdminix/anaconda3/envs/apaut/lib/python3.7/site-packages/pymongo/collection.py\", line 761, in insert_many\n",
      "    blk.execute(write_concern, session=session)\n",
      "  File \"/home/cdminix/anaconda3/envs/apaut/lib/python3.7/site-packages/pymongo/bulk.py\", line 528, in execute\n",
      "    return self.execute_command(generator, write_concern, session)\n",
      "  File \"/home/cdminix/anaconda3/envs/apaut/lib/python3.7/site-packages/pymongo/bulk.py\", line 358, in execute_command\n",
      "    with client._tmp_session(session) as s:\n",
      "  File \"/home/cdminix/anaconda3/envs/apaut/lib/python3.7/contextlib.py\", line 112, in __enter__\n",
      "    return next(self.gen)\n",
      "  File \"/home/cdminix/anaconda3/envs/apaut/lib/python3.7/site-packages/pymongo/mongo_client.py\", line 1829, in _tmp_session\n",
      "    s = self._ensure_session(session)\n",
      "  File \"/home/cdminix/anaconda3/envs/apaut/lib/python3.7/site-packages/pymongo/mongo_client.py\", line 1816, in _ensure_session\n",
      "    return self.__start_session(True, causal_consistency=False)\n",
      "  File \"/home/cdminix/anaconda3/envs/apaut/lib/python3.7/site-packages/pymongo/mongo_client.py\", line 1766, in __start_session\n",
      "    server_session = self._get_server_session()\n",
      "  File \"/home/cdminix/anaconda3/envs/apaut/lib/python3.7/site-packages/pymongo/mongo_client.py\", line 1802, in _get_server_session\n",
      "    return self._topology.get_server_session()\n",
      "  File \"/home/cdminix/anaconda3/envs/apaut/lib/python3.7/site-packages/pymongo/topology.py\", line 493, in get_server_session\n",
      "    None)\n",
      "  File \"/home/cdminix/anaconda3/envs/apaut/lib/python3.7/site-packages/pymongo/topology.py\", line 217, in _select_servers_loop\n",
      "    (self._error_message(selector), timeout, self.description))\n",
      "pymongo.errors.ServerSelectionTimeoutError: cluster0-shard-00-01.pdjrf.mongodb.net:27017: [Errno -3] Temporary failure in name resolution,cluster0-shard-00-00.pdjrf.mongodb.net:27017: [Errno -3] Temporary failure in name resolution,cluster0-shard-00-02.pdjrf.mongodb.net:27017: [Errno -3] Temporary failure in name resolution, Timeout: 30s, Topology Description: <TopologyDescription id: 6019537e3d526681967b0979, topology_type: ReplicaSetNoPrimary, servers: [<ServerDescription ('cluster0-shard-00-00.pdjrf.mongodb.net', 27017) server_type: Unknown, rtt: None, error=AutoReconnect('cluster0-shard-00-00.pdjrf.mongodb.net:27017: [Errno -3] Temporary failure in name resolution')>, <ServerDescription ('cluster0-shard-00-01.pdjrf.mongodb.net', 27017) server_type: Unknown, rtt: None, error=AutoReconnect('cluster0-shard-00-01.pdjrf.mongodb.net:27017: [Errno -3] Temporary failure in name resolution')>, <ServerDescription ('cluster0-shard-00-02.pdjrf.mongodb.net', 27017) server_type: Unknown, rtt: None, error=AutoReconnect('cluster0-shard-00-02.pdjrf.mongodb.net:27017: [Errno -3] Temporary failure in name resolution')>]>\n",
      "\n",
      "Exception in thread Thread-617:\n",
      "Traceback (most recent call last):\n",
      "  File \"/home/cdminix/anaconda3/envs/apaut/lib/python3.7/threading.py\", line 926, in _bootstrap_inner\n",
      "    self.run()\n",
      "  File \"/home/cdminix/anaconda3/envs/apaut/lib/python3.7/threading.py\", line 870, in run\n",
      "    self._target(*self._args, **self._kwargs)\n",
      "  File \"/home/cdminix/anaconda3/envs/apaut/lib/python3.7/site-packages/pymongo/collection.py\", line 761, in insert_many\n",
      "    blk.execute(write_concern, session=session)\n",
      "  File \"/home/cdminix/anaconda3/envs/apaut/lib/python3.7/site-packages/pymongo/bulk.py\", line 528, in execute\n",
      "    return self.execute_command(generator, write_concern, session)\n",
      "  File \"/home/cdminix/anaconda3/envs/apaut/lib/python3.7/site-packages/pymongo/bulk.py\", line 358, in execute_command\n",
      "    with client._tmp_session(session) as s:\n",
      "  File \"/home/cdminix/anaconda3/envs/apaut/lib/python3.7/contextlib.py\", line 112, in __enter__\n",
      "    return next(self.gen)\n",
      "  File \"/home/cdminix/anaconda3/envs/apaut/lib/python3.7/site-packages/pymongo/mongo_client.py\", line 1829, in _tmp_session\n",
      "    s = self._ensure_session(session)\n",
      "  File \"/home/cdminix/anaconda3/envs/apaut/lib/python3.7/site-packages/pymongo/mongo_client.py\", line 1816, in _ensure_session\n",
      "    return self.__start_session(True, causal_consistency=False)\n",
      "  File \"/home/cdminix/anaconda3/envs/apaut/lib/python3.7/site-packages/pymongo/mongo_client.py\", line 1766, in __start_session\n",
      "    server_session = self._get_server_session()\n",
      "  File \"/home/cdminix/anaconda3/envs/apaut/lib/python3.7/site-packages/pymongo/mongo_client.py\", line 1802, in _get_server_session\n",
      "    return self._topology.get_server_session()\n",
      "  File \"/home/cdminix/anaconda3/envs/apaut/lib/python3.7/site-packages/pymongo/topology.py\", line 493, in get_server_session\n",
      "    None)\n",
      "  File \"/home/cdminix/anaconda3/envs/apaut/lib/python3.7/site-packages/pymongo/topology.py\", line 217, in _select_servers_loop\n",
      "    (self._error_message(selector), timeout, self.description))\n",
      "pymongo.errors.ServerSelectionTimeoutError: cluster0-shard-00-01.pdjrf.mongodb.net:27017: [Errno -3] Temporary failure in name resolution,cluster0-shard-00-00.pdjrf.mongodb.net:27017: [Errno -3] Temporary failure in name resolution,cluster0-shard-00-02.pdjrf.mongodb.net:27017: [Errno -3] Temporary failure in name resolution, Timeout: 30s, Topology Description: <TopologyDescription id: 6019537e3d526681967b0979, topology_type: ReplicaSetNoPrimary, servers: [<ServerDescription ('cluster0-shard-00-00.pdjrf.mongodb.net', 27017) server_type: Unknown, rtt: None, error=AutoReconnect('cluster0-shard-00-00.pdjrf.mongodb.net:27017: [Errno -3] Temporary failure in name resolution')>, <ServerDescription ('cluster0-shard-00-01.pdjrf.mongodb.net', 27017) server_type: Unknown, rtt: None, error=AutoReconnect('cluster0-shard-00-01.pdjrf.mongodb.net:27017: [Errno -3] Temporary failure in name resolution')>, <ServerDescription ('cluster0-shard-00-02.pdjrf.mongodb.net', 27017) server_type: Unknown, rtt: None, error=AutoReconnect('cluster0-shard-00-02.pdjrf.mongodb.net:27017: [Errno -3] Temporary failure in name resolution')>]>\n",
      "\n"
     ]
    }
   ],
   "source": [
    "batch_size = 1_000\n",
    "#i = 0\n",
    "#r_i = 0\n",
    "\n",
    "insert_thread = None\n",
    "\n",
    "\n",
    "#lsh_store = LSH(chunksize=batch_size)\n",
    "\n",
    "max_entries = db['review_data'].count()\n",
    "#max_entries = 1_001\n",
    "\n",
    "for review in tqdm(db['review_data'].find(), total=max_entries-i):\n",
    "    if i >= max_entries:\n",
    "        lsh_store.flush()\n",
    "        break\n",
    "    if i % batch_size == 0:\n",
    "        if i > 0:\n",
    "            review_l = []\n",
    "            sentence_l = []\n",
    "            start_index_l = []\n",
    "            end_index_l = []\n",
    "            for j, val in enumerate(splitter.split(texts)):\n",
    "                for k, sentence in enumerate(val):\n",
    "                    sentence = str(sentence)\n",
    "                    strip_sentence = sentence.strip()\n",
    "                    if len(strip_sentence) > 0:\n",
    "                        review_l.append(ids[j])\n",
    "                        sentence_l.append(strip_sentence)\n",
    "                        if k >= 1:\n",
    "                            start_index_l.append(end_index_l[-1] + 1)\n",
    "                        else:\n",
    "                            start_index_l.append(0)\n",
    "                        end_index_l.append(start_index_l[-1] + len(sentence))\n",
    "            embeddings = model.encode(sentence_l, convert_to_tensor=True)\n",
    "            insert_list = []\n",
    "            for k, (indv_review, sentence, start_index, end_index) in enumerate(zip(\n",
    "                review_l,\n",
    "                embeddings,\n",
    "                start_index_l,\n",
    "                end_index_l\n",
    "            )):\n",
    "                lsh_store.add(sentence.numpy(), r_i)\n",
    "                insert_list.append({\n",
    "                    '_id': r_i,\n",
    "                    'review_id': indv_review,\n",
    "                    's': start_index,\n",
    "                    'e': end_index,\n",
    "                })\n",
    "                r_i += 1\n",
    "            insert_thread = Thread(target=db['sentence_data'].insert_many, args=(insert_list,))\n",
    "            insert_thread.start()\n",
    "        texts = []\n",
    "        ids = []\n",
    "    texts.append(zlib.decompress(review['review_text']).decode())\n",
    "    ids.append(review['_id'])\n",
    "    i += 1"
   ]
  },
  {
   "cell_type": "code",
   "execution_count": 10,
   "metadata": {},
   "outputs": [],
   "source": [
    "lsh_store.flush()"
   ]
  },
  {
   "cell_type": "markdown",
   "metadata": {},
   "source": [
    "# Vector Quantization Tests"
   ]
  },
  {
   "cell_type": "code",
   "execution_count": 17,
   "metadata": {},
   "outputs": [],
   "source": [
    "import pickle5 as pickle\n",
    "with open('test.pkl', \"rb\") as f:\n",
    "  data = pickle.load(f)\n",
    "data_small = data.sample(100_000, random_state=42)"
   ]
  },
  {
   "cell_type": "code",
   "execution_count": 18,
   "metadata": {},
   "outputs": [],
   "source": [
    "n = 1000  #chunk row size\n",
    "list_df = [data_small[i:i+n] for i in range(0,data_small.shape[0],n)]"
   ]
  },
  {
   "cell_type": "code",
   "execution_count": 19,
   "metadata": {},
   "outputs": [
    {
     "data": {
      "application/vnd.jupyter.widget-view+json": {
       "model_id": "3505a37efc8b4e9086841050266e5fcf",
       "version_major": 2,
       "version_minor": 0
      },
      "text/plain": [
       "HBox(children=(FloatProgress(value=0.0), HTML(value='')))"
      ]
     },
     "metadata": {},
     "output_type": "display_data"
    },
    {
     "name": "stdout",
     "output_type": "stream",
     "text": [
      "\n"
     ]
    }
   ],
   "source": [
    "corpus_embeddings = []\n",
    "orig_reviews = data_small.index.values.tolist()\n",
    "for df in tqdm(list_df):\n",
    "    corpus_embeddings += model.encode(df['review_text'].values, convert_to_tensor=True)"
   ]
  },
  {
   "cell_type": "code",
   "execution_count": 68,
   "metadata": {},
   "outputs": [],
   "source": [
    "from sentence_transformers import SentenceTransformer, util\n",
    "import torch\n",
    "\n",
    "def run_query(queries, quant=32):\n",
    "\n",
    "    # Find the closest 5 sentences of the corpus for each query sentence based on cosine similarity\n",
    "    top_k = min(5, len(corpus_embeddings))\n",
    "    for query_text in queries:\n",
    "        query = model.encode(query_text, convert_to_tensor=True)\n",
    "        corpus = torch.stack(corpus_embeddings)\n",
    "\n",
    "        if quant == 16:\n",
    "            corpus = torch.tensor(corpus.numpy().astype('float16').astype('float32'))\n",
    "            query = torch.tensor(query.numpy().astype('float16').astype('float32'))\n",
    "        if quant == 8:\n",
    "            corpus = np.asarray(corpus * 128, dtype=np.int8).astype('float32')\n",
    "            query = np.asarray(query * 128, dtype=np.int8).astype('float32')\n",
    "\n",
    "        cos_scores = util.pytorch_cos_sim(query, corpus)[0]\n",
    "        cos_scores = cos_scores.cpu()\n",
    "\n",
    "        #We use torch.topk to find the highest 5 scores\n",
    "        top_results = torch.topk(cos_scores, k=top_k)\n",
    "\n",
    "        print(\"\\n\\n======================\\n\\n\")\n",
    "        print(\"Query:\", query_text)\n",
    "        print(\"Quantization:\", quant)\n",
    "        print(\"\\nTop 5 most similar sentences in corpus:\")\n",
    "\n",
    "        for score, idx in zip(top_results[0], top_results[1]):\n",
    "            print(data.loc[orig_reviews[idx]]['review_text'], \"(Score: %.4f)\" % (score))"
   ]
  },
  {
   "cell_type": "code",
   "execution_count": 69,
   "metadata": {},
   "outputs": [
    {
     "name": "stdout",
     "output_type": "stream",
     "text": [
      "\n",
      "\n",
      "======================\n",
      "\n",
      "\n",
      "Query: blew my socks off\n",
      "Quantization: 32\n",
      "\n",
      "Top 5 most similar sentences in corpus:\n",
      "I laughed my ass off. (Score: 0.5259)\n",
      "Blew me away!!!! (Score: 0.5193)\n",
      "Blew me away! Twisted and unique. (Score: 0.4619)\n",
      "Scared the hell out of me... (Score: 0.4187)\n",
      "Sucked. (Score: 0.4004)\n",
      "\n",
      "\n",
      "======================\n",
      "\n",
      "\n",
      "Query: decent film\n",
      "Quantization: 32\n",
      "\n",
      "Top 5 most similar sentences in corpus:\n",
      "Decent story (Score: 0.5028)\n",
      "Great book,really good movie (Score: 0.5020)\n",
      "spectacular novel (Score: 0.4965)\n",
      "very similar to the movie (Score: 0.4911)\n",
      "The movie is better. (Score: 0.4860)\n",
      "\n",
      "\n",
      "======================\n",
      "\n",
      "\n",
      "Query: quite bad\n",
      "Quantization: 32\n",
      "\n",
      "Top 5 most similar sentences in corpus:\n",
      "Very bad. (Score: 0.8503)\n",
      "Not terrible, but pretty bad. (Score: 0.7357)\n",
      "Not great.... (Score: 0.7232)\n",
      "Not bad. Not great, but not bad. (Score: 0.6885)\n",
      "Not wonderful. (Score: 0.6870)\n",
      "\n",
      "\n",
      "======================\n",
      "\n",
      "\n",
      "Query: could have more dogs\n",
      "Quantization: 32\n",
      "\n",
      "Top 5 most similar sentences in corpus:\n",
      "Did not have enough fire-cats. Please add more fire-cats. (Score: 0.4206)\n",
      "Rather than write a review, I'll point you here. \n",
      " http://women.timesonline.co.uk/tol/li... \n",
      " A Factoid: Research shows that Dog owners are 9X more likely to survive one year after a heart attack than NonDog owners. (Cat owners are about even). I think there might be some adverse selection here as those who aren't mobile most likely have to find new homes for their dogs. \n",
      " It's worth reading but a little dry being so evidence based. (Score: 0.4074)\n",
      "i need to read more diverse books. (Score: 0.3755)\n",
      "If you even like dogs, you will love this book. (Score: 0.3704)\n",
      "could have been longer (Score: 0.3642)\n",
      "\n",
      "\n",
      "======================\n",
      "\n",
      "\n",
      "Query: peperami\n",
      "Quantization: 32\n",
      "\n",
      "Top 5 most similar sentences in corpus:\n",
      "Master Murakami (Score: 0.4711)\n",
      "Pesimo. (Score: 0.4697)\n",
      "ji (Score: 0.4218)\n",
      "Lame-o (Score: 0.3838)\n",
      "Polu gluko \n",
      " (Apo ta diegemata tou New Yorker) (Score: 0.3833)\n"
     ]
    }
   ],
   "source": [
    "run_query([\n",
    "    'blew my socks off',\n",
    "    'decent film',\n",
    "    'quite bad',\n",
    "    'could have more dogs',\n",
    "    'peperami'\n",
    "], quant=32)"
   ]
  },
  {
   "cell_type": "code",
   "execution_count": 70,
   "metadata": {},
   "outputs": [
    {
     "name": "stdout",
     "output_type": "stream",
     "text": [
      "\n",
      "\n",
      "======================\n",
      "\n",
      "\n",
      "Query: blew my socks off\n",
      "Quantization: 16\n",
      "\n",
      "Top 5 most similar sentences in corpus:\n",
      "I laughed my ass off. (Score: 0.5260)\n",
      "Blew me away!!!! (Score: 0.5193)\n",
      "Blew me away! Twisted and unique. (Score: 0.4619)\n",
      "Scared the hell out of me... (Score: 0.4187)\n",
      "Sucked. (Score: 0.4003)\n",
      "\n",
      "\n",
      "======================\n",
      "\n",
      "\n",
      "Query: decent film\n",
      "Quantization: 16\n",
      "\n",
      "Top 5 most similar sentences in corpus:\n",
      "Decent story (Score: 0.5028)\n",
      "Great book,really good movie (Score: 0.5020)\n",
      "spectacular novel (Score: 0.4965)\n",
      "very similar to the movie (Score: 0.4911)\n",
      "The movie is better. (Score: 0.4860)\n",
      "\n",
      "\n",
      "======================\n",
      "\n",
      "\n",
      "Query: quite bad\n",
      "Quantization: 16\n",
      "\n",
      "Top 5 most similar sentences in corpus:\n",
      "Very bad. (Score: 0.8503)\n",
      "Not terrible, but pretty bad. (Score: 0.7357)\n",
      "Not great.... (Score: 0.7232)\n",
      "Not bad. Not great, but not bad. (Score: 0.6885)\n",
      "Not wonderful. (Score: 0.6870)\n",
      "\n",
      "\n",
      "======================\n",
      "\n",
      "\n",
      "Query: could have more dogs\n",
      "Quantization: 16\n",
      "\n",
      "Top 5 most similar sentences in corpus:\n",
      "Did not have enough fire-cats. Please add more fire-cats. (Score: 0.4206)\n",
      "Rather than write a review, I'll point you here. \n",
      " http://women.timesonline.co.uk/tol/li... \n",
      " A Factoid: Research shows that Dog owners are 9X more likely to survive one year after a heart attack than NonDog owners. (Cat owners are about even). I think there might be some adverse selection here as those who aren't mobile most likely have to find new homes for their dogs. \n",
      " It's worth reading but a little dry being so evidence based. (Score: 0.4074)\n",
      "i need to read more diverse books. (Score: 0.3755)\n",
      "If you even like dogs, you will love this book. (Score: 0.3704)\n",
      "could have been longer (Score: 0.3642)\n",
      "\n",
      "\n",
      "======================\n",
      "\n",
      "\n",
      "Query: peperami\n",
      "Quantization: 16\n",
      "\n",
      "Top 5 most similar sentences in corpus:\n",
      "Master Murakami (Score: 0.4711)\n",
      "Pesimo. (Score: 0.4697)\n",
      "ji (Score: 0.4218)\n",
      "Lame-o (Score: 0.3838)\n",
      "Polu gluko \n",
      " (Apo ta diegemata tou New Yorker) (Score: 0.3833)\n"
     ]
    }
   ],
   "source": [
    "run_query([\n",
    "    'blew my socks off',\n",
    "    'decent film',\n",
    "    'quite bad',\n",
    "    'could have more dogs',\n",
    "    'peperami'\n",
    "], quant=16)"
   ]
  },
  {
   "cell_type": "code",
   "execution_count": 71,
   "metadata": {},
   "outputs": [
    {
     "name": "stdout",
     "output_type": "stream",
     "text": [
      "\n",
      "\n",
      "======================\n",
      "\n",
      "\n",
      "Query: blew my socks off\n",
      "Quantization: 8\n",
      "\n",
      "Top 5 most similar sentences in corpus:\n",
      "Blew me away!!!! (Score: 0.4751)\n",
      "I laughed my ass off. (Score: 0.4402)\n",
      "Blew me away! Twisted and unique. (Score: 0.4246)\n",
      "Scared the hell out of me... (Score: 0.3950)\n",
      "Creepy and abrupt! House of Leaves scared my pants off! Like literally my pants jumped off and ran away and I am now in my under ware!!!! (Score: 0.3657)\n",
      "\n",
      "\n",
      "======================\n",
      "\n",
      "\n",
      "Query: decent film\n",
      "Quantization: 8\n",
      "\n",
      "Top 5 most similar sentences in corpus:\n",
      "Great book,really good movie (Score: 0.5018)\n",
      "spectacular novel (Score: 0.4851)\n",
      "very similar to the movie (Score: 0.4850)\n",
      "Good book, so was the movie (Score: 0.4723)\n",
      "Decent story (Score: 0.4707)\n",
      "\n",
      "\n",
      "======================\n",
      "\n",
      "\n",
      "Query: quite bad\n",
      "Quantization: 8\n",
      "\n",
      "Top 5 most similar sentences in corpus:\n",
      "Very bad. (Score: 0.8193)\n",
      "Not terrible, but pretty bad. (Score: 0.7040)\n",
      "Not great.... (Score: 0.6986)\n",
      "Not wonderful. (Score: 0.6644)\n",
      "Not bad. Not great, but not bad. (Score: 0.6587)\n",
      "\n",
      "\n",
      "======================\n",
      "\n",
      "\n",
      "Query: could have more dogs\n",
      "Quantization: 8\n",
      "\n",
      "Top 5 most similar sentences in corpus:\n",
      "Rather than write a review, I'll point you here. \n",
      " http://women.timesonline.co.uk/tol/li... \n",
      " A Factoid: Research shows that Dog owners are 9X more likely to survive one year after a heart attack than NonDog owners. (Cat owners are about even). I think there might be some adverse selection here as those who aren't mobile most likely have to find new homes for their dogs. \n",
      " It's worth reading but a little dry being so evidence based. (Score: 0.4084)\n",
      "Did not have enough fire-cats. Please add more fire-cats. (Score: 0.4032)\n",
      "i need to read more diverse books. (Score: 0.3754)\n",
      "I thought it was a really cute story. Would have loved to have read more. (Score: 0.3632)\n",
      "Lovely stories about recsued dogs. (Score: 0.3542)\n",
      "\n",
      "\n",
      "======================\n",
      "\n",
      "\n",
      "Query: peperami\n",
      "Quantization: 8\n",
      "\n",
      "Top 5 most similar sentences in corpus:\n",
      "Master Murakami (Score: 0.4521)\n",
      "Pesimo. (Score: 0.3630)\n",
      "What Sarah pi said. (Score: 0.3231)\n",
      "Hehehehehe...:P (Score: 0.3100)\n",
      "Polu gluko \n",
      " (Apo ta diegemata tou New Yorker) (Score: 0.3090)\n"
     ]
    }
   ],
   "source": [
    "run_query([\n",
    "    'blew my socks off',\n",
    "    'decent film',\n",
    "    'quite bad',\n",
    "    'could have more dogs',\n",
    "    'peperami'\n",
    "], quant=8)"
   ]
  }
 ],
 "metadata": {
  "kernelspec": {
   "display_name": "Python 3",
   "language": "python",
   "name": "python3"
  },
  "language_info": {
   "codemirror_mode": {
    "name": "ipython",
    "version": 3
   },
   "file_extension": ".py",
   "mimetype": "text/x-python",
   "name": "python",
   "nbconvert_exporter": "python",
   "pygments_lexer": "ipython3",
   "version": "3.7.8"
  }
 },
 "nbformat": 4,
 "nbformat_minor": 4
}
